Workbook

Sheet Warehouse_Transactions
A1: Transaction_ID | B1: Date | C1: Product_ID | D1: Product_Name | E1: Category | F1: Transaction_Type | G1: Quantity | H1: Supplier | I1: Warehouse_Location | J1: Unit_Cost | K1: Damaged_Qty | L1: Processing_Time_Hours | M1: Status
A2: TRX001 | B2: 46024 | C2: PRD013 | D2: Pulpen Gel Hitam | E2: Alat Tulis | F2: Inbound | G2: 69 | H2: CV Prima Office | I2: Rack D1 | J2: 6500 | K2: 0 | L2: 8.1 | M2: Completed
A3: TRX002 | B3: 46024 | C3: PRD003 | D3: Teh Celup 25 Sachet | E3: Minuman | F3: Inbound | G3: 27 | H3: PT Sumber Segar | I3: Rack A2 | J3: 11200 | K3: 1 | L3: 3.5 | M3: Completed
A4: TRX003 | B4: 46025 | C4: PRD017 | D4: Kabel Ekstensi 3 Meter | E4: Elektronik | F4: Outbound | G4: 17 | H4: PT Cahaya Elektrik | I4: Rack D1 | J4: 68500 | K4: 0 | L4: 4.1 | M4: Completed
A5: TRX004 | B5: 46027 | C5: PRD010 | D5: Pembersih Lantai 800 ml | E5: Kebersihan | F5: Outbound | G5: 25 | H5: PT Bersih Sentosa | I5: Rack C2 | J5: 13900 | K5: 0 | L5: 12.4 | M5: Delayed
A6: TRX005 | B6: 46028 | C6: PRD012 | D6: Kertas A4 80 gsm | E6: Alat Tulis | F6: Inbound | G6: 48 | H6: CV Prima Office | I6: Rack D1 | J6: 54500 | K6: 0 | L6: 12.1 | M6: Pending
A7: TRX006 | B7: 46028 | C7: PRD007 | D7: Minyak Goreng 1 L | E7: Makanan | F7: Inbound | G7: 63 | H7: CV Pangan Makmur | I7: Rack B2 | J7: 17200 | K7: 0 | L7: 6 | M7: Completed
A8: TRX007 | B8: 46032 | C8: PRD017 | D8: Kabel Ekstensi 3 Meter | E8: Elektronik | F8: Inbound | G8: 100 | H8: PT Cahaya Elektrik | I8: Rack D1 | J8: 68500 | K8: 0 | L8: 10.8 | M8: Pending
A9: TRX008 | B9: 46032 | C9: PRD003 | D9: Teh Celup 25 Sachet | E9: Minuman | F9: Inbound | G9: 67 | H9: PT Sumber Segar | I9: Rack A2 | J9: 11200 | K9: 0 | L9: 4.8 | M9: Completed
A10: TRX009 | B10: 46034 | C10: PRD012 | D10: Kertas A4 80 gsm | E10: Alat Tulis | F10: Inbound | G10: 22 | H10: CV Prima Office | I10: Rack D1 | J10: 54500 | K10: 0 | L10: 4.3 | M10: Completed
A11: TRX010 | B11: 46038 | C11: PRD017 | D11: Kabel Ekstensi 3 Meter | E11: Elektronik | F11: Inbound | G11: 73 | H11: PT Cahaya Elektrik | I11: Rack D1 | J11: 68500 | K11: 0 | L11: 4.4 | M11: Completed
A12: TRX011 | B12: 46038 | C12: PRD013 | D12: Pulpen Gel Hitam | E12: Alat Tulis | F12: Inbound | G12: 46 | H12: CV Prima Office | I12: Rack D1 | J12: 6500 | K12: 0 | L12: 5.8 | M12: Completed
A13: TRX012 | B13: 46039 | C13: PRD001 | D13: Air Mineral 600 ml | E13: Minuman | F13: Inbound | G13: 50 | H13: PT Sumber Segar | I13: Rack A1 | J13: 3200 | K13: 0 | L13: 10.7 | M13: Pending
... A101: TRX100 | B101: 46200 | C101: PRD011 | D101: Tisu Gulung 10 Roll | E101: Kebersihan | F101: Outbound | G101: 67 | H101: PT Bersih Sentosa | I101: Rack C2 | J101: 28500 | K101: 5 | L101: 5.5 | M101: Completed

Sheet Analysis_Data
A1: Transaction_ID | B1: Date | C1: Product_ID | D1: Product_Name | E1: Category | F1: Transaction_Type | G1: Quantity | H1: Supplier | I1: Warehouse_Location | J1: Unit_Cost | K1: Damaged_Qty | L1: Processing_Time_Hours | M1: Status | N1: Month | O1: Transaction_Value | P1: Net_Good_Qty | Q1: Signed_Quantity | R1: Damage_Rate | S1: Delayed_Flag | T1: Pending_Flag | U1: High_Process_Flag | V1: Column1 | W1: Inbound_Qty | X1: Outbound_Qty | Y1: Inbound_Value | Z1: Outbound_Value
A2: TRX001 | B2: 46024 | C2: PRD013 | D2: Pulpen Gel Hitam | E2: Alat Tulis | F2: Inbound | G2: 69 | H2: CV Prima Office | I2: Rack D1 | J2: 6500 | K2: 0 | L2: 8.1 | M2: Completed | N2: =DATE(YEAR(WarehouseTransactions3[[#This Row],[Date]]),MONTH(WarehouseTransactions3[[#This Row],[Date]]),1) -> 46023 | O2: =WarehouseTransactions3[[#This Row],[Quantity]]*WarehouseTransactions3[[#This Row],[Unit_Cost]] -> 448500 | P2: =WarehouseTransactions3[[#This Row],[Quantity]]-WarehouseTransactions3[[#This Row],[Damaged_Qty]] -> 69 | Q2: =IF(WarehouseTransactions3[[#This Row],[Transaction_Type]]="Inbound",WarehouseTransactions3[[#This Row],[Quantity]],-WarehouseTransactions3[[#This Row],[Quantity]]) -> 69 | R2: =IFERROR(WarehouseTransactions3[[#This Row],[Damaged_Qty]]/WarehouseTransactions3[[#This Row],[Quantity]],0) -> 0 | S2: =IF(WarehouseTransactions3[[#This Row],[Status]]="Delayed",1,0) -> 0 | T2: =IF(WarehouseTransactions3[[#This Row],[Status]]="Pending",1,0) -> 0 | U2: =IF(WarehouseTransactions3[[#This Row],[Processing_Time_Hours]]>8,1,0) -> 1 | V2: =WarehouseTransactions3[[#This Row],[Processing_Time_Hours]]/24 -> 0.3375 | W2: =IF(WarehouseTransactions3[[#This Row],[Transaction_Type]]="Inbound",WarehouseTransactions3[[#This Row],[Quantity]],0) -> 69 | X2: =IF(WarehouseTransactions3[[#This Row],[Transaction_Type]]="Outbound",WarehouseTransactions3[[#This Row],[Quantity]],0) -> 0 | Y2: =IF(WarehouseTransactions3[[#This Row],[Transaction_Type]]="Inbound",WarehouseTransactions3[[#This Row],[Transaction_Value]],0) -> 448500 | Z2: =IF(WarehouseTransactions3[[#This Row],[Transaction_Type]]="Outbound",WarehouseTransactions3[[#This Row],[Transaction_Value]],0) -> 0
A3: TRX002 | B3: 46024 | C3: PRD003 | D3: Teh Celup 25 Sachet | E3: Minuman | F3: Inbound | G3: 27 | H3: PT Sumber Segar | I3: Rack A2 | J3: 11200 | K3: 1 | L3: 3.5 | M3: Completed | N3: =DATE(YEAR(WarehouseTransactions3[[#This Row],[Date]]),MONTH(WarehouseTransactions3[[#This Row],[Date]]),1) -> 46023 | O3: =WarehouseTransactions3[[#This Row],[Quantity]]*WarehouseTransactions3[[#This Row],[Unit_Cost]] -> 302400 | P3: =WarehouseTransactions3[[#This Row],[Quantity]]-WarehouseTransactions3[[#This Row],[Damaged_Qty]] -> 26 | Q3: =IF(WarehouseTransactions3[[#This Row],[Transaction_Type]]="Inbound",WarehouseTransactions3[[#This Row],[Quantity]],-WarehouseTransactions3[[#This Row],[Quantity]]) -> 27 | R3: =IFERROR(WarehouseTransactions3[[#This Row],[Damaged_Qty]]/WarehouseTransactions3[[#This Row],[Quantity]],0) -> 0.037037037 | S3: =IF(WarehouseTransactions3[[#This Row],[Status]]="Delayed",1,0) -> 0 | T3: =IF(WarehouseTransactions3[[#This Row],[Status]]="Pending",1,0) -> 0 | U3: =IF(WarehouseTransactions3[[#This Row],[Processing_Time_Hours]]>8,1,0) -> 0 | V3: =WarehouseTransactions3[[#This Row],[Processing_Time_Hours]]/24 -> 0.14583333 | W3: =IF(WarehouseTransactions3[[#This Row],[Transaction_Type]]="Inbound",WarehouseTransactions3[[#This Row],[Quantity]],0) -> 27 | X3: =IF(WarehouseTransactions3[[#This Row],[Transaction_Type]]="Outbound",WarehouseTransactions3[[#This Row],[Quantity]],0) -> 0 | Y3: =IF(WarehouseTransactions3[[#This Row],[Transaction_Type]]="Inbound",WarehouseTransactions3[[#This Row],[Transaction_Value]],0) -> 302400 | Z3: =IF(WarehouseTransactions3[[#This Row],[Transaction_Type]]="Outbound",WarehouseTransactions3[[#This Row],[Transaction_Value]],0) -> 0
A4: TRX003 | B4: 46025 | C4: PRD017 | D4: Kabel Ekstensi 3 Meter | E4: Elektronik | F4: Outbound | G4: 17 | H4: PT Cahaya Elektrik | I4: Rack D1 | J4: 68500 | K4: 0 | L4: 4.1 | M4: Completed | N4: =DATE(YEAR(WarehouseTransactions3[[#This Row],[Date]]),MONTH(WarehouseTransactions3[[#This Row],[Date]]),1) -> 46023 | O4: =WarehouseTransactions3[[#This Row],[Quantity]]*WarehouseTransactions3[[#This Row],[Unit_Cost]] -> 1164500 | P4: =WarehouseTransactions3[[#This Row],[Quantity]]-WarehouseTransactions3[[#This Row],[Damaged_Qty]] -> 17 | Q4: =IF(WarehouseTransactions3[[#This Row],[Transaction_Type]]="Inbound",WarehouseTransactions3[[#This Row],[Quantity]],-WarehouseTransactions3[[#This Row],[Quantity]]) -> -17 | R4: =IFERROR(WarehouseTransactions3[[#This Row],[Damaged_Qty]]/WarehouseTransactions3[[#This Row],[Quantity]],0) -> 0 | S4: =IF(WarehouseTransactions3[[#This Row],[Status]]="Delayed",1,0) -> 0 | T4: =IF(WarehouseTransactions3[[#This Row],[Status]]="Pending",1,0) -> 0 | U4: =IF(WarehouseTransactions3[[#This Row],[Processing_Time_Hours]]>8,1,0) -> 0 | V4: =WarehouseTransactions3[[#This Row],[Processing_Time_Hours]]/24 -> 0.17083333 | W4: =IF(WarehouseTransactions3[[#This Row],[Transaction_Type]]="Inbound",WarehouseTransactions3[[#This Row],[Quantity]],0) -> 0 | X4: =IF(WarehouseTransactions3[[#This Row],[Transaction_Type]]="Outbound",WarehouseTransactions3[[#This Row],[Quantity]],0) -> 17 | Y4: =IF(WarehouseTransactions3[[#This Row],[Transaction_Type]]="Inbound",WarehouseTransactions3[[#This Row],[Transaction_Value]],0) -> 0 | Z4: =IF(WarehouseTransactions3[[#This Row],[Transaction_Type]]="Outbound",WarehouseTransactions3[[#This Row],[Transaction_Value]],0) -> 1164500
A5: TRX004 | B5: 46027 | C5: PRD010 | D5: Pembersih Lantai 800 ml | E5: Kebersihan | F5: Outbound | G5: 25 | H5: PT Bersih Sentosa | I5: Rack C2 | J5: 13900 | K5: 0 | L5: 12.4 | M5: Delayed | N5: =DATE(YEAR(WarehouseTransactions3[[#This Row],[Date]]),MONTH(WarehouseTransactions3[[#This Row],[Date]]),1) -> 46023 | O5: =WarehouseTransactions3[[#This Row],[Quantity]]*WarehouseTransactions3[[#This Row],[Unit_Cost]] -> 347500 | P5: =WarehouseTransactions3[[#This Row],[Quantity]]-WarehouseTransactions3[[#This Row],[Damaged_Qty]] -> 25 | Q5: =IF(WarehouseTransactions3[[#This Row],[Transaction_Type]]="Inbound",WarehouseTransactions3[[#This Row],[Quantity]],-WarehouseTransactions3[[#This Row],[Quantity]]) -> -25 | R5: =IFERROR(WarehouseTransactions3[[#This Row],[Damaged_Qty]]/WarehouseTransactions3[[#This Row],[Quantity]],0) -> 0 | S5: =IF(WarehouseTransactions3[[#This Row],[Status]]="Delayed",1,0) -> 1 | T5: =IF(WarehouseTransactions3[[#This Row],[Status]]="Pending",1,0) -> 0 | U5: =IF(WarehouseTransactions3[[#This Row],[Processing_Time_Hours]]>8,1,0) -> 1 | V5: =WarehouseTransactions3[[#This Row],[Processing_Time_Hours]]/24 -> 0.51666667 | W5: =IF(WarehouseTransactions3[[#This Row],[Transaction_Type]]="Inbound",WarehouseTransactions3[[#This Row],[Quantity]],0) -> 0 | X5: =IF(WarehouseTransactions3[[#This Row],[Transaction_Type]]="Outbound",WarehouseTransactions3[[#This Row],[Quantity]],0) -> 25 | Y5: =IF(WarehouseTransactions3[[#This Row],[Transaction_Type]]="Inbound",WarehouseTransactions3[[#This Row],[Transaction_Value]],0) -> 0 | Z5: =IF(WarehouseTransactions3[[#This Row],[Transaction_Type]]="Outbound",WarehouseTransactions3[[#This Row],[Transaction_Value]],0) -> 347500
A6: TRX005 | B6: 46028 | C6: PRD012 | D6: Kertas A4 80 gsm | E6: Alat Tulis | F6: Inbound | G6: 48 | H6: CV Prima Office | I6: Rack D1 | J6: 54500 | K6: 0 | L6: 12.1 | M6: Pending | N6: =DATE(YEAR(WarehouseTransactions3[[#This Row],[Date]]),MONTH(WarehouseTransactions3[[#This Row],[Date]]),1) -> 46023 | O6: =WarehouseTransactions3[[#This Row],[Quantity]]*WarehouseTransactions3[[#This Row],[Unit_Cost]] -> 2616000 | P6: =WarehouseTransactions3[[#This Row],[Quantity]]-WarehouseTransactions3[[#This Row],[Damaged_Qty]] -> 48 | Q6: =IF(WarehouseTransactions3[[#This Row],[Transaction_Type]]="Inbound",WarehouseTransactions3[[#This Row],[Quantity]],-WarehouseTransactions3[[#This Row],[Quantity]]) -> 48 | R6: =IFERROR(WarehouseTransactions3[[#This Row],[Damaged_Qty]]/WarehouseTransactions3[[#This Row],[Quantity]],0) -> 0 | S6: =IF(WarehouseTransactions3[[#This Row],[Status]]="Delayed",1,0) -> 0 | T6: =IF(WarehouseTransactions3[[#This Row],[Status]]="Pending",1,0) -> 1 | U6: =IF(WarehouseTransactions3[[#This Row],[Processing_Time_Hours]]>8,1,0) -> 1 | V6: =WarehouseTransactions3[[#This Row],[Processing_Time_Hours]]/24 -> 0.50416667 | W6: =IF(WarehouseTransactions3[[#This Row],[Transaction_Type]]="Inbound",WarehouseTransactions3[[#This Row],[Quantity]],0) -> 48 | X6: =IF(WarehouseTransactions3[[#This Row],[Transaction_Type]]="Outbound",WarehouseTransactions3[[#This Row],[Quantity]],0) -> 0 | Y6: =IF(WarehouseTransactions3[[#This Row],[Transaction_Type]]="Inbound",WarehouseTransactions3[[#This Row],[Transaction_Value]],0) -> 2616000 | Z6: =IF(WarehouseTransactions3[[#This Row],[Transaction_Type]]="Outbound",WarehouseTransactions3[[#This Row],[Transaction_Value]],0) -> 0
A7: TRX006 | B7: 46028 | C7: PRD007 | D7: Minyak Goreng 1 L | E7: Makanan | F7: Inbound | G7: 63 | H7: CV Pangan Makmur | I7: Rack B2 | J7: 17200 | K7: 0 | L7: 6 | M7: Completed | N7: =DATE(YEAR(WarehouseTransactions3[[#This Row],[Date]]),MONTH(WarehouseTransactions3[[#This Row],[Date]]),1) -> 46023 | O7: =WarehouseTransactions3[[#This Row],[Quantity]]*WarehouseTransactions3[[#This Row],[Unit_Cost]] -> 1083600 | P7: =WarehouseTransactions3[[#This Row],[Quantity]]-WarehouseTransactions3[[#This Row],[Damaged_Qty]] -> 63 | Q7: =IF(WarehouseTransactions3[[#This Row],[Transaction_Type]]="Inbound",WarehouseTransactions3[[#This Row],[Quantity]],-WarehouseTransactions3[[#This Row],[Quantity]]) -> 63 | R7: =IFERROR(WarehouseTransactions3[[#This Row],[Damaged_Qty]]/WarehouseTransactions3[[#This Row],[Quantity]],0) -> 0 | S7: =IF(WarehouseTransactions3[[#This Row],[Status]]="Delayed",1,0) -> 0 | T7: =IF(WarehouseTransactions3[[#This Row],[Status]]="Pending",1,0) -> 0 | U7: =IF(WarehouseTransactions3[[#This Row],[Processing_Time_Hours]]>8,1,0) -> 0 | V7: =WarehouseTransactions3[[#This Row],[Processing_Time_Hours]]/24 -> 0.25 | W7: =IF(WarehouseTransactions3[[#This Row],[Transaction_Type]]="Inbound",WarehouseTransactions3[[#This Row],[Quantity]],0) -> 63 | X7: =IF(WarehouseTransactions3[[#This Row],[Transaction_Type]]="Outbound",WarehouseTransactions3[[#This Row],[Quantity]],0) -> 0 | Y7: =IF(WarehouseTransactions3[[#This Row],[Transaction_Type]]="Inbound",WarehouseTransactions3[[#This Row],[Transaction_Value]],0) -> 1083600 | Z7: =IF(WarehouseTransactions3[[#This Row],[Transaction_Type]]="Outbound",WarehouseTransactions3[[#This Row],[Transaction_Value]],0) -> 0
A8: TRX007 | B8: 46032 | C8: PRD017 | D8: Kabel Ekstensi 3 Meter | E8: Elektronik | F8: Inbound | G8: 100 | H8: PT Cahaya Elektrik | I8: Rack D1 | J8: 68500 | K8: 0 | L8: 10.8 | M8: Pending | N8: =DATE(YEAR(WarehouseTransactions3[[#This Row],[Date]]),MONTH(WarehouseTransactions3[[#This Row],[Date]]),1) -> 46023 | O8: =WarehouseTransactions3[[#This Row],[Quantity]]*WarehouseTransactions3[[#This Row],[Unit_Cost]] -> 6850000 | P8: =WarehouseTransactions3[[#This Row],[Quantity]]-WarehouseTransactions3[[#This Row],[Damaged_Qty]] -> 100 | Q8: =IF(WarehouseTransactions3[[#This Row],[Transaction_Type]]="Inbound",WarehouseTransactions3[[#This Row],[Quantity]],-WarehouseTransactions3[[#This Row],[Quantity]]) -> 100 | R8: =IFERROR(WarehouseTransactions3[[#This Row],[Damaged_Qty]]/WarehouseTransactions3[[#This Row],[Quantity]],0) -> 0 | S8: =IF(WarehouseTransactions3[[#This Row],[Status]]="Delayed",1,0) -> 0 | T8: =IF(WarehouseTransactions3[[#This Row],[Status]]="Pending",1,0) -> 1 | U8: =IF(WarehouseTransactions3[[#This Row],[Processing_Time_Hours]]>8,1,0) -> 1 | V8: =WarehouseTransactions3[[#This Row],[Processing_Time_Hours]]/24 -> 0.45 | W8: =IF(WarehouseTransactions3[[#This Row],[Transaction_Type]]="Inbound",WarehouseTransactions3[[#This Row],[Quantity]],0) -> 100 | X8: =IF(WarehouseTransactions3[[#This Row],[Transaction_Type]]="Outbound",WarehouseTransactions3[[#This Row],[Quantity]],0) -> 0 | Y8: =IF(WarehouseTransactions3[[#This Row],[Transaction_Type]]="Inbound",WarehouseTransactions3[[#This Row],[Transaction_Value]],0) -> 6850000 | Z8: =IF(WarehouseTransactions3[[#This Row],[Transaction_Type]]="Outbound",WarehouseTransactions3[[#This Row],[Transaction_Value]],0) -> 0
A9: TRX008 | B9: 46032 | C9: PRD003 | D9: Teh Celup 25 Sachet | E9: Minuman | F9: Inbound | G9: 67 | H9: PT Sumber Segar | I9: Rack A2 | J9: 11200 | K9: 0 | L9: 4.8 | M9: Completed | N9: =DATE(YEAR(WarehouseTransactions3[[#This Row],[Date]]),MONTH(WarehouseTransactions3[[#This Row],[Date]]),1) -> 46023 | O9: =WarehouseTransactions3[[#This Row],[Quantity]]*WarehouseTransactions3[[#This Row],[Unit_Cost]] -> 750400 | P9: =WarehouseTransactions3[[#This Row],[Quantity]]-WarehouseTransactions3[[#This Row],[Damaged_Qty]] -> 67 | Q9: =IF(WarehouseTransactions3[[#This Row],[Transaction_Type]]="Inbound",WarehouseTransactions3[[#This Row],[Quantity]],-WarehouseTransactions3[[#This Row],[Quantity]]) -> 67 | R9: =IFERROR(WarehouseTransactions3[[#This Row],[Damaged_Qty]]/WarehouseTransactions3[[#This Row],[Quantity]],0) -> 0 | S9: =IF(WarehouseTransactions3[[#This Row],[Status]]="Delayed",1,0) -> 0 | T9: =IF(WarehouseTransactions3[[#This Row],[Status]]="Pending",1,0) -> 0 | U9: =IF(WarehouseTransactions3[[#This Row],[Processing_Time_Hours]]>8,1,0) -> 0 | V9: =WarehouseTransactions3[[#This Row],[Processing_Time_Hours]]/24 -> 0.2 | W9: =IF(WarehouseTransactions3[[#This Row],[Transaction_Type]]="Inbound",WarehouseTransactions3[[#This Row],[Quantity]],0) -> 67 | X9: =IF(WarehouseTransactions3[[#This Row],[Transaction_Type]]="Outbound",WarehouseTransactions3[[#This Row],[Quantity]],0) -> 0 | Y9: =IF(WarehouseTransactions3[[#This Row],[Transaction_Type]]="Inbound",WarehouseTransactions3[[#This Row],[Transaction_Value]],0) -> 750400 | Z9: =IF(WarehouseTransactions3[[#This Row],[Transaction_Type]]="Outbound",WarehouseTransactions3[[#This Row],[Transaction_Value]],0) -> 0
A10: TRX009 | B10: 46034 | C10: PRD012 | D10: Kertas A4 80 gsm | E10: Alat Tulis | F10: Inbound | G10: 22 | H10: CV Prima Office | I10: Rack D1 | J10: 54500 | K10: 0 | L10: 4.3 | M10: Completed | N10: =DATE(YEAR(WarehouseTransactions3[[#This Row],[Date]]),MONTH(WarehouseTransactions3[[#This Row],[Date]]),1) -> 46023 | O10: =WarehouseTransactions3[[#This Row],[Quantity]]*WarehouseTransactions3[[#This Row],[Unit_Cost]] -> 1199000 | P10: =WarehouseTransactions3[[#This Row],[Quantity]]-WarehouseTransactions3[[#This Row],[Damaged_Qty]] -> 22 | Q10: =IF(WarehouseTransactions3[[#This Row],[Transaction_Type]]="Inbound",WarehouseTransactions3[[#This Row],[Quantity]],-WarehouseTransactions3[[#This Row],[Quantity]]) -> 22 | R10: =IFERROR(WarehouseTransactions3[[#This Row],[Damaged_Qty]]/WarehouseTransactions3[[#This Row],[Quantity]],0) -> 0 | S10: =IF(WarehouseTransactions3[[#This Row],[Status]]="Delayed",1,0) -> 0 | T10: =IF(WarehouseTransactions3[[#This Row],[Status]]="Pending",1,0) -> 0 | U10: =IF(WarehouseTransactions3[[#This Row],[Processing_Time_Hours]]>8,1,0) -> 0 | V10: =WarehouseTransactions3[[#This Row],[Processing_Time_Hours]]/24 -> 0.17916667 | W10: =IF(WarehouseTransactions3[[#This Row],[Transaction_Type]]="Inbound",WarehouseTransactions3[[#This Row],[Quantity]],0) -> 22 | X10: =IF(WarehouseTransactions3[[#This Row],[Transaction_Type]]="Outbound",WarehouseTransactions3[[#This Row],[Quantity]],0) -> 0 | Y10: =IF(WarehouseTransactions3[[#This Row],[Transaction_Type]]="Inbound",WarehouseTransactions3[[#This Row],[Transaction_Value]],0) -> 1199000 | Z10: =IF(WarehouseTransactions3[[#This Row],[Transaction_Type]]="Outbound",WarehouseTransactions3[[#This Row],[Transaction_Value]],0) -> 0
A11: TRX010 | B11: 46038 | C11: PRD017 | D11: Kabel Ekstensi 3 Meter | E11: Elektronik | F11: Inbound | G11: 73 | H11: PT Cahaya Elektrik | I11: Rack D1 | J11: 68500 | K11: 0 | L11: 4.4 | M11: Completed | N11: =DATE(YEAR(WarehouseTransactions3[[#This Row],[Date]]),MONTH(WarehouseTransactions3[[#This Row],[Date]]),1) -> 46023 | O11: =WarehouseTransactions3[[#This Row],[Quantity]]*WarehouseTransactions3[[#This Row],[Unit_Cost]] -> 5000500 | P11: =WarehouseTransactions3[[#This Row],[Quantity]]-WarehouseTransactions3[[#This Row],[Damaged_Qty]] -> 73 | Q11: =IF(WarehouseTransactions3[[#This Row],[Transaction_Type]]="Inbound",WarehouseTransactions3[[#This Row],[Quantity]],-WarehouseTransactions3[[#This Row],[Quantity]]) -> 73 | R11: =IFERROR(WarehouseTransactions3[[#This Row],[Damaged_Qty]]/WarehouseTransactions3[[#This Row],[Quantity]],0) -> 0 | S11: =IF(WarehouseTransactions3[[#This Row],[Status]]="Delayed",1,0) -> 0 | T11: =IF(WarehouseTransactions3[[#This Row],[Status]]="Pending",1,0) -> 0 | U11: =IF(WarehouseTransactions3[[#This Row],[Processing_Time_Hours]]>8,1,0) -> 0 | V11: =WarehouseTransactions3[[#This Row],[Processing_Time_Hours]]/24 -> 0.18333333 | W11: =IF(WarehouseTransactions3[[#This Row],[Transaction_Type]]="Inbound",WarehouseTransactions3[[#This Row],[Quantity]],0) -> 73 | X11: =IF(WarehouseTransactions3[[#This Row],[Transaction_Type]]="Outbound",WarehouseTransactions3[[#This Row],[Quantity]],0) -> 0 | Y11: =IF(WarehouseTransactions3[[#This Row],[Transaction_Type]]="Inbound",WarehouseTransactions3[[#This Row],[Transaction_Value]],0) -> 5000500 | Z11: =IF(WarehouseTransactions3[[#This Row],[Transaction_Type]]="Outbound",WarehouseTransactions3[[#This Row],[Transaction_Value]],0) -> 0
A12: TRX011 | B12: 46038 | C12: PRD013 | D12: Pulpen Gel Hitam | E12: Alat Tulis | F12: Inbound | G12: 46 | H12: CV Prima Office | I12: Rack D1 | J12: 6500 | K12: 0 | L12: 5.8 | M12: Completed | N12: =DATE(YEAR(WarehouseTransactions3[[#This Row],[Date]]),MONTH(WarehouseTransactions3[[#This Row],[Date]]),1) -> 46023 | O12: =WarehouseTransactions3[[#This Row],[Quantity]]*WarehouseTransactions3[[#This Row],[Unit_Cost]] -> 299000 | P12: =WarehouseTransactions3[[#This Row],[Quantity]]-WarehouseTransactions3[[#This Row],[Damaged_Qty]] -> 46 | Q12: =IF(WarehouseTransactions3[[#This Row],[Transaction_Type]]="Inbound",WarehouseTransactions3[[#This Row],[Quantity]],-WarehouseTransactions3[[#This Row],[Quantity]]) -> 46 | R12: =IFERROR(WarehouseTransactions3[[#This Row],[Damaged_Qty]]/WarehouseTransactions3[[#This Row],[Quantity]],0) -> 0 | S12: =IF(WarehouseTransactions3[[#This Row],[Status]]="Delayed",1,0) -> 0 | T12: =IF(WarehouseTransactions3[[#This Row],[Status]]="Pending",1,0) -> 0 | U12: =IF(WarehouseTransactions3[[#This Row],[Processing_Time_Hours]]>8,1,0) -> 0 | V12: =WarehouseTransactions3[[#This Row],[Processing_Time_Hours]]/24 -> 0.24166667 | W12: =IF(WarehouseTransactions3[[#This Row],[Transaction_Type]]="Inbound",WarehouseTransactions3[[#This Row],[Quantity]],0) -> 46 | X12: =IF(WarehouseTransactions3[[#This Row],[Transaction_Type]]="Outbound",WarehouseTransactions3[[#This Row],[Quantity]],0) -> 0 | Y12: =IF(WarehouseTransactions3[[#This Row],[Transaction_Type]]="Inbound",WarehouseTransactions3[[#This Row],[Transaction_Value]],0) -> 299000 | Z12: =IF(WarehouseTransactions3[[#This Row],[Transaction_Type]]="Outbound",WarehouseTransactions3[[#This Row],[Transaction_Value]],0) -> 0
A13: TRX012 | B13: 46039 | C13: PRD001 | D13: Air Mineral 600 ml | E13: Minuman | F13: Inbound | G13: 50 | H13: PT Sumber Segar | I13: Rack A1 | J13: 3200 | K13: 0 | L13: 10.7 | M13: Pending | N13: =DATE(YEAR(WarehouseTransactions3[[#This Row],[Date]]),MONTH(WarehouseTransactions3[[#This Row],[Date]]),1) -> 46023 | O13: =WarehouseTransactions3[[#This Row],[Quantity]]*WarehouseTransactions3[[#This Row],[Unit_Cost]] -> 160000 | P13: =WarehouseTransactions3[[#This Row],[Quantity]]-WarehouseTransactions3[[#This Row],[Damaged_Qty]] -> 50 | Q13: =IF(WarehouseTransactions3[[#This Row],[Transaction_Type]]="Inbound",WarehouseTransactions3[[#This Row],[Quantity]],-WarehouseTransactions3[[#This Row],[Quantity]]) -> 50 | R13: =IFERROR(WarehouseTransactions3[[#This Row],[Damaged_Qty]]/WarehouseTransactions3[[#This Row],[Quantity]],0) -> 0 | S13: =IF(WarehouseTransactions3[[#This Row],[Status]]="Delayed",1,0) -> 0 | T13: =IF(WarehouseTransactions3[[#This Row],[Status]]="Pending",1,0) -> 1 | U13: =IF(WarehouseTransactions3[[#This Row],[Processing_Time_Hours]]>8,1,0) -> 1 | V13: =WarehouseTransactions3[[#This Row],[Processing_Time_Hours]]/24 -> 0.44583333 | W13: =IF(WarehouseTransactions3[[#This Row],[Transaction_Type]]="Inbound",WarehouseTransactions3[[#This Row],[Quantity]],0) -> 50 | X13: =IF(WarehouseTransactions3[[#This Row],[Transaction_Type]]="Outbound",WarehouseTransactions3[[#This Row],[Quantity]],0) -> 0 | Y13: =IF(WarehouseTransactions3[[#This Row],[Transaction_Type]]="Inbound",WarehouseTransactions3[[#This Row],[Transaction_Value]],0) -> 160000 | Z13: =IF(WarehouseTransactions3[[#This Row],[Transaction_Type]]="Outbound",WarehouseTransactions3[[#This Row],[Transaction_Value]],0) -> 0
... A101: TRX100 | B101: 46200 | C101: PRD011 | D101: Tisu Gulung 10 Roll | E101: Kebersihan | F101: Outbound | G101: 67 | H101: PT Bersih Sentosa | I101: Rack C2 | J101: 28500 | K101: 5 | L101: 5.5 | M101: Completed | N101: =DATE(YEAR(WarehouseTransactions3[[#This Row],[Date]]),MONTH(WarehouseTransactions3[[#This Row],[Date]]),1) -> 46174 | O101: =WarehouseTransactions3[[#This Row],[Quantity]]*WarehouseTransactions3[[#This Row],[Unit_Cost]] -> 1909500 | P101: =WarehouseTransactions3[[#This Row],[Quantity]]-WarehouseTransactions3[[#This Row],[Damaged_Qty]] -> 62 | Q101: =IF(WarehouseTransactions3[[#This Row],[Transaction_Type]]="Inbound",WarehouseTransactions3[[#This Row],[Quantity]],-WarehouseTransactions3[[#This Row],[Quantity]]) -> -67 | R101: =IFERROR(WarehouseTransactions3[[#This Row],[Damaged_Qty]]/WarehouseTransactions3[[#This Row],[Quantity]],0) -> 0.074626866 | S101: =IF(WarehouseTransactions3[[#This Row],[Status]]="Delayed",1,0) -> 0 | T101: =IF(WarehouseTransactions3[[#This Row],[Status]]="Pending",1,0) -> 0 | U101: =IF(WarehouseTransactions3[[#This Row],[Processing_Time_Hours]]>8,1,0) -> 0 | V101: =WarehouseTransactions3[[#This Row],[Processing_Time_Hours]]/24 -> 0.22916667 | W101: =IF(WarehouseTransactions3[[#This Row],[Transaction_Type]]="Inbound",WarehouseTransactions3[[#This Row],[Quantity]],0) -> 0 | X101: =IF(WarehouseTransactions3[[#This Row],[Transaction_Type]]="Outbound",WarehouseTransactions3[[#This Row],[Quantity]],0) -> 67 | Y101: =IF(WarehouseTransactions3[[#This Row],[Transaction_Type]]="Inbound",WarehouseTransactions3[[#This Row],[Transaction_Value]],0) -> 0 | Z101: =IF(WarehouseTransactions3[[#This Row],[Transaction_Type]]="Outbound",WarehouseTransactions3[[#This Row],[Transaction_Value]],0) -> 1909500

Sheet Pivot_Analysis
A2: Monthly Activity | P2: Month | Q2: Inbound
A3: Months (Month) | B3: Days (Month) | C3: Month | D3: Sum of Inbound_Qty | E3: Sum of Outbound_Qty | F3: Sum of Inbound_Value | G3: Sum of Outbound_Value | H3: Count of Product_ID | I3: Sum of Damaged_Qty | J3: Average of Processing_Time_Hours
A4: Jan | D4: 664 | E4: 124 | F4: 19406900 | G4: 2413200 | H4: 17 | I4: 3 | J4: 6.3294118 | P4: Jan 26 | Q4: {=D4:D9} -> 664
A5: Feb | D5: 591 | E5: 559 | F5: 13486600 | G5: 12743900 | H5: 17 | I5: 3 | J5: 4.7705882 | P5: Feb 26 | Q5: 591
A6: Mar | D6: 434 | E6: 489 | F6: 12257800 | G6: 10117200 | H6: 16 | I6: 11 | J6: 5.6875 | P6: Mar 26 | Q6: 434
A7: Apr | D7: 488 | E7: 468 | F7: 5866300 | G7: 6745600 | H7: 17 | I7: 9 | J7: 4.7470588 | P7: April 26 | Q7: 488
A8: May | D8: 255 | E8: 567 | F8: 2757900 | G8: 12145200 | H8: 17 | I8: 2 | J8: 5.9235294 | P8: May 26 | Q8: 255
A9: Jun | D9: 554 | E9: 511 | F9: 6816100 | G9: 8214400 | H9: 16 | I9: 6 | J9: 4.925 | P9: Jun 26 | Q9: 554
A10: Grand Total | D10: 2986 | E10: 2718 | F10: 60591600 | G10: 52379500 | H10: 100 | I10: 34 | J10: 5.399
A13: Product Movement
A14: Product_Name | B14: Category | C14: Sum of Inbound_Qty | D14: Sum of Outbound_Qty | E14: Sum of Quantity
A15: Lakban Bening 48 mm | B15: Alat Tulis | C15: 158 | D15: 467 | E15: 625
A16: Mi Instan Goreng | B16: Makanan | C16: 372 | D16: 87 | E16: 459
A17: Lampu LED 12 Watt | B17: Elektronik | C17: 155 | D17: 267 | E17: 422
A18: Buku Tulis A5 | B18: Alat Tulis | C18: 314 | D18: 106 | E18: 420
A19: Baterai AA Isi 4 | B19: Elektronik | C19: 169 | D19: 237 | E19: 406
A20: Kertas A4 80 gsm | B20: Alat Tulis | C20: 262 | D20: 119 | E20: 381
A21: Pulpen Gel Hitam | B21: Alat Tulis | C21: 276 | D21: 97 | E21: 373
A22: Teh Celup 25 Sachet | B22: Minuman | C22: 94 | D22: 256 | E22: 350
A23: Grand Total | C23: 1800 | D23: 1636 | E23: 3436
A36: Category Activity
A37: Category | B37: Sum of Inbound_Qty | C37: Sum of Outbound_Qty | D37: Sum of Quantity | E37: Sum of Transaction_Value
A38: Alat Tulis | B38: 1010 | C38: 789 | D38: 1799 | E38: 34215000
A39: Elektronik | B39: 497 | C39: 571 | D39: 1068 | E39: 41505800
A40: Kebersihan | B40: 232 | C40: 549 | D40: 781 | E40: 15763800
A41: Makanan | B41: 988 | C41: 159 | D41: 1147 | E41: 11677300
A42: Minuman | B42: 259 | C42: 650 | D42: 909 | E42: 9809200
A43: Grand Total | B43: 2986 | C43: 2718 | D43: 5704 | E43: 112971100
A46: Supplier Performance
A47: Supplier | B47: Count of Transaction_ID | C47: Sum of Quantity | D47: Sum of Damaged_Qty | E47: Average of Processing_Time_Hours
A48: CV Pangan Makmur | B48: 19 | C48: 1147 | D48: 7 | E48: 5.5947368
A49: CV Prima Office | B49: 30 | C49: 1799 | D49: 1 | E49: 5.48
A50: PT Bersih Sentosa | B50: 19 | C50: 781 | D50: 12 | E50: 6.1578947
A51: PT Cahaya Elektrik | B51: 17 | C51: 1068 | D51: 13 | E51: 5.2294118
A52: PT Sumber Segar | B52: 15 | C52: 909 | D52: 1 | E52: 4.22
A53: Grand Total | B53: 100 | C53: 5704 | D53: 34 | E53: 5.399
A56: Warehouse Location Activity
A57: Warehouse_Location | B57: Sum of Inbound_Qty | C57: Sum of Outbound_Qty | D57: Sum of Quantity | E57: Count of Transaction_ID
A58: Rack A1 | B58: 165 | C58: 394 | D58: 559 | E58: 8
A59: Rack A2 | B59: 94 | C59: 256 | D59: 350 | E59: 7
...

Sheet Dashboard
A2: Warehouse performance dashboard
A3: Transactions from January to June 2026
S4: Month | T4: Inbound | U4: Outbound | W4: Product | Y4: Total Movement | AA4: Category | AB4: Inbound | AC4: Outbound | AE4: Location | AF4: Total Qty | AH4: Status | AI4: Transaction | AK4: Supplier | AL4: Damaged Qty
A5: Total Inbound Quantity | E5: Total Outbound Quantity | I5: Net stock movement
A6: =SUMIF(Analysis_Data!F2:F101,"Inbound",Analysis_Data!G2:G101) -> 2986 | E6: =SUMIF(Analysis_Data!F2:F101,"Outbound",Analysis_Data!G2:G101) -> 2718 | I6: =A6-E6 -> 268 | S6: Jan 2026 | T6: {=Pivot_Analysis!D4:D9} -> 664 | U6: {=Pivot_Analysis!E4:E9} -> 124 | W6: {=Pivot_Analysis!A15:A22} -> Lakban Bening 48 mm | Y6: {=Pivot_Analysis!E15:E22} -> 625 | AA6: {=Pivot_Analysis!A38:A42} -> Alat Tulis | AB6: {=Pivot_Analysis!B38:B42} -> 1010 | AC6: {=Pivot_Analysis!C38:C42} -> 789 | AE6: {=Pivot_Analysis!A58:A65} -> Rack A1 | AF6: {=Pivot_Analysis!D58:D65} -> 559 | AH6: {=Pivot_Analysis!A74:A76} -> Completed | AI6: {=Pivot_Analysis!B74:B76} -> 80 | AK6: {=Pivot_Analysis!A48:A52} -> CV Pangan Makmur | AL6: {=Pivot_Analysis!D48:D52} -> 7
S7: Feb 2026 | T7: 591 | U7: 559 | W7: Mi Instan Goreng | Y7: 459 | AA7: Elektronik | AB7: 497 | AC7: 571 | AE7: Rack A2 | AF7: 350 | AH7: Delayed | AI7: 10 | AK7: CV Prima Office | AL7: 1
S8: Mar 2026 | T8: 434 | U8: 489 | W8: Lampu LED 12 Watt | Y8: 422 | AA8: Kebersihan | AB8: 232 | AC8: 549 | AE8: Rack B1 | AF8: 552 | AH8: Pending | AI8: 10 | AK8: PT Bersih Sentosa | AL8: 12
A9: Inbound Value | E9: Outbound Value | I9: Overall Damage Rate | S9: Apr 2026 | T9: 488 | U9: 468 | W9: Buku Tulis A5 | Y9: 420 | AA9: Makanan | AB9: 988 | AC9: 159 | AE9: Rack B2 | AF9: 595 | AK9: PT Cahaya Elektrik | AL9: 13
A10: =SUMIF(Analysis_Data!F2:F101,"Inbound",Analysis_Data!O2:O101) -> 60591600 | E10: =SUMIF(Analysis_Data!F2:F101,"Outbound",Analysis_Data!O2:O101) -> 52379500 | I10: =IFERROR(SUM(Analysis_Data!K2:K101)/SUM(Analysis_Data!G2:G101),0) -> 0.0059607293 | S10: Mei 2026 | T10: 255 | U10: 567 | W10: Baterai AA Isi 4 | Y10: 406 | AA10: Minuman | AB10: 259 | AC10: 650 | AE10: Rack C1 | AF10: 205 | AK10: PT Sumber Segar | AL10: 1
S11: Jun 2026 | T11: 554 | U11: 511 | W11: Kertas A4 80 gsm | Y11: 381 | AE11: Rack C2 | AF11: 576
W12: Pulpen Gel Hitam | Y12: 373 | AE12: Rack D1 | AF12: 994
A13: Delayed Transactions | E13: Pending Transactions | I13: Completion Rate | W13: Teh Celup 25 Sachet | Y13: 350 | AE13: Rack D2 | AF13: 1873
A14: =COUNTIF(Analysis_Data!M2:M101,"Delayed") -> 10 | E14: =COUNTIF(Analysis_Data!M2:M101,"Pending") -> 10 | I14: =COUNTIF(Analysis_Data!M2:M101,"Completed")/COUNTA(Analysis_Data!A2:A101) -> 0.8
